Watching for file changes with StatReloader
Watching for file changes with StatReloader
/Users/yassineelmoudene/Desktop/Devs/avocat_web/api/models.py changed, reloading.
Watching for file changes with StatReloader
"POST /api/token/ HTTP/1.1" 401 79
"POST /api/token/ HTTP/1.1" 401 79
"POST /api/token/ HTTP/1.1" 200 628
"GET /api/fonctionclients/ HTTP/1.1" 200 2
Internal Server Error: /api/typeclients/
Traceback (most recent call last):
  File "/Users/yassineelmoudene/Desktop/Devs/Venv/lib/python3.13/site-packages/django/db/backends/utils.py", line 105, in _execute
    return self.cursor.execute(sql, params)
           ~~~~~~~~~~~~~~~~~~~^^^^^^^^^^^^^
  File "/Users/yassineelmoudene/Desktop/Devs/Venv/lib/python3.13/site-packages/django/db/backends/mysql/base.py", line 76, in execute
    return self.cursor.execute(query, args)
           ~~~~~~~~~~~~~~~~~~~^^^^^^^^^^^^^
  File "/Users/yassineelmoudene/Desktop/Devs/Venv/lib/python3.13/site-packages/MySQLdb/cursors.py", line 179, in execute
    res = self._query(mogrified_query)
  File "/Users/yassineelmoudene/Desktop/Devs/Venv/lib/python3.13/site-packages/MySQLdb/cursors.py", line 330, in _query
    db.query(q)
    ~~~~~~~~^^^
  File "/Users/yassineelmoudene/Desktop/Devs/Venv/lib/python3.13/site-packages/MySQLdb/connections.py", line 261, in query
    _mysql.connection.query(self, query)
    ~~~~~~~~~~~~~~~~~~~~~~~^^^^^^^^^^^^^
MySQLdb.OperationalError: (1054, "Unknown column 'type_client.libelleTypeClient_fr' in 'field list'")

The above exception was the direct cause of the following exception:

Traceback (most recent call last):
  File "/Users/yassineelmoudene/Desktop/Devs/Venv/lib/python3.13/site-packages/django/core/handlers/exception.py", line 55, in inner
    response = get_response(request)
  File "/Users/yassineelmoudene/Desktop/Devs/Venv/lib/python3.13/site-packages/django/core/handlers/base.py", line 197, in _get_response
    response = wrapped_callback(request, *callback_args, **callback_kwargs)
  File "/Users/yassineelmoudene/Desktop/Devs/Venv/lib/python3.13/site-packages/django/views/decorators/csrf.py", line 65, in _view_wrapper
    return view_func(request, *args, **kwargs)
  File "/Users/yassineelmoudene/Desktop/Devs/Venv/lib/python3.13/site-packages/rest_framework/viewsets.py", line 125, in view
    return self.dispatch(request, *args, **kwargs)
           ~~~~~~~~~~~~~^^^^^^^^^^^^^^^^^^^^^^^^^^
  File "/Users/yassineelmoudene/Desktop/Devs/Venv/lib/python3.13/site-packages/rest_framework/views.py", line 515, in dispatch
    response = self.handle_exception(exc)
  File "/Users/yassineelmoudene/Desktop/Devs/Venv/lib/python3.13/site-packages/rest_framework/views.py", line 475, in handle_exception
    self.raise_uncaught_exception(exc)
    ~~~~~~~~~~~~~~~~~~~~~~~~~~~~~^^^^^
  File "/Users/yassineelmoudene/Desktop/Devs/Venv/lib/python3.13/site-packages/rest_framework/views.py", line 486, in raise_uncaught_exception
    raise exc
  File "/Users/yassineelmoudene/Desktop/Devs/Venv/lib/python3.13/site-packages/rest_framework/views.py", line 512, in dispatch
    response = handler(request, *args, **kwargs)
  File "/Users/yassineelmoudene/Desktop/Devs/Venv/lib/python3.13/site-packages/rest_framework/mixins.py", line 46, in list
    return Response(serializer.data)
                    ^^^^^^^^^^^^^^^
  File "/Users/yassineelmoudene/Desktop/Devs/Venv/lib/python3.13/site-packages/rest_framework/serializers.py", line 797, in data
    ret = super().data
          ^^^^^^^^^^^^
  File "/Users/yassineelmoudene/Desktop/Devs/Venv/lib/python3.13/site-packages/rest_framework/serializers.py", line 251, in data
    self._data = self.to_representation(self.instance)
                 ~~~~~~~~~~~~~~~~~~~~~~^^^^^^^^^^^^^^^
  File "/Users/yassineelmoudene/Desktop/Devs/Venv/lib/python3.13/site-packages/rest_framework/serializers.py", line 716, in to_representation
    self.child.to_representation(item) for item in iterable
                                                   ^^^^^^^^
  File "/Users/yassineelmoudene/Desktop/Devs/Venv/lib/python3.13/site-packages/django/db/models/query.py", line 400, in __iter__
    self._fetch_all()
    ~~~~~~~~~~~~~~~^^
  File "/Users/yassineelmoudene/Desktop/Devs/Venv/lib/python3.13/site-packages/django/db/models/query.py", line 1928, in _fetch_all
    self._result_cache = list(self._iterable_class(self))
                         ~~~~^^^^^^^^^^^^^^^^^^^^^^^^^^^^
  File "/Users/yassineelmoudene/Desktop/Devs/Venv/lib/python3.13/site-packages/django/db/models/query.py", line 91, in __iter__
    results = compiler.execute_sql(
        chunked_fetch=self.chunked_fetch, chunk_size=self.chunk_size
    )
  File "/Users/yassineelmoudene/Desktop/Devs/Venv/lib/python3.13/site-packages/django/db/models/sql/compiler.py", line 1574, in execute_sql
    cursor.execute(sql, params)
    ~~~~~~~~~~~~~~^^^^^^^^^^^^^
  File "/Users/yassineelmoudene/Desktop/Devs/Venv/lib/python3.13/site-packages/django/db/backends/utils.py", line 122, in execute
    return super().execute(sql, params)
           ~~~~~~~~~~~~~~~^^^^^^^^^^^^^
  File "/Users/yassineelmoudene/Desktop/Devs/Venv/lib/python3.13/site-packages/django/db/backends/utils.py", line 79, in execute
    return self._execute_with_wrappers(
           ~~~~~~~~~~~~~~~~~~~~~~~~~~~^
        sql, params, many=False, executor=self._execute
        ^^^^^^^^^^^^^^^^^^^^^^^^^^^^^^^^^^^^^^^^^^^^^^^
    )
    ^
  File "/Users/yassineelmoudene/Desktop/Devs/Venv/lib/python3.13/site-packages/django/db/backends/utils.py", line 92, in _execute_with_wrappers
    return executor(sql, params, many, context)
  File "/Users/yassineelmoudene/Desktop/Devs/Venv/lib/python3.13/site-packages/django/db/backends/utils.py", line 100, in _execute
    with self.db.wrap_database_errors:
         ^^^^^^^^^^^^^^^^^^^^^^^^^^^^
  File "/Users/yassineelmoudene/Desktop/Devs/Venv/lib/python3.13/site-packages/django/db/utils.py", line 91, in __exit__
    raise dj_exc_value.with_traceback(traceback) from exc_value
  File "/Users/yassineelmoudene/Desktop/Devs/Venv/lib/python3.13/site-packages/django/db/backends/utils.py", line 105, in _execute
    return self.cursor.execute(sql, params)
           ~~~~~~~~~~~~~~~~~~~^^^^^^^^^^^^^
  File "/Users/yassineelmoudene/Desktop/Devs/Venv/lib/python3.13/site-packages/django/db/backends/mysql/base.py", line 76, in execute
    return self.cursor.execute(query, args)
           ~~~~~~~~~~~~~~~~~~~^^^^^^^^^^^^^
  File "/Users/yassineelmoudene/Desktop/Devs/Venv/lib/python3.13/site-packages/MySQLdb/cursors.py", line 179, in execute
    res = self._query(mogrified_query)
  File "/Users/yassineelmoudene/Desktop/Devs/Venv/lib/python3.13/site-packages/MySQLdb/cursors.py", line 330, in _query
    db.query(q)
    ~~~~~~~~^^^
  File "/Users/yassineelmoudene/Desktop/Devs/Venv/lib/python3.13/site-packages/MySQLdb/connections.py", line 261, in query
    _mysql.connection.query(self, query)
    ~~~~~~~~~~~~~~~~~~~~~~~^^^^^^^^^^^^^
django.db.utils.OperationalError: (1054, "Unknown column 'type_client.libelleTypeClient_fr' in 'field list'")
"GET /api/typeclients/ HTTP/1.1" 500 186076
"GET /api/statutaffaires/ HTTP/1.1" 200 2
"GET /api/typetribunals/ HTTP/1.1" 200 2
"GET /api/tribunals/ HTTP/1.1" 200 2
Internal Server Error: /api/typeclients/
Traceback (most recent call last):
  File "/Users/yassineelmoudene/Desktop/Devs/Venv/lib/python3.13/site-packages/django/db/backends/utils.py", line 105, in _execute
    return self.cursor.execute(sql, params)
           ~~~~~~~~~~~~~~~~~~~^^^^^^^^^^^^^
  File "/Users/yassineelmoudene/Desktop/Devs/Venv/lib/python3.13/site-packages/django/db/backends/mysql/base.py", line 76, in execute
    return self.cursor.execute(query, args)
           ~~~~~~~~~~~~~~~~~~~^^^^^^^^^^^^^
  File "/Users/yassineelmoudene/Desktop/Devs/Venv/lib/python3.13/site-packages/MySQLdb/cursors.py", line 179, in execute
    res = self._query(mogrified_query)
  File "/Users/yassineelmoudene/Desktop/Devs/Venv/lib/python3.13/site-packages/MySQLdb/cursors.py", line 330, in _query
    db.query(q)
    ~~~~~~~~^^^
  File "/Users/yassineelmoudene/Desktop/Devs/Venv/lib/python3.13/site-packages/MySQLdb/connections.py", line 261, in query
    _mysql.connection.query(self, query)
    ~~~~~~~~~~~~~~~~~~~~~~~^^^^^^^^^^^^^
MySQLdb.OperationalError: (1054, "Unknown column 'type_client.libelleTypeClient_fr' in 'field list'")

The above exception was the direct cause of the following exception:

Traceback (most recent call last):
  File "/Users/yassineelmoudene/Desktop/Devs/Venv/lib/python3.13/site-packages/django/core/handlers/exception.py", line 55, in inner
    response = get_response(request)
  File "/Users/yassineelmoudene/Desktop/Devs/Venv/lib/python3.13/site-packages/django/core/handlers/base.py", line 197, in _get_response
    response = wrapped_callback(request, *callback_args, **callback_kwargs)
  File "/Users/yassineelmoudene/Desktop/Devs/Venv/lib/python3.13/site-packages/django/views/decorators/csrf.py", line 65, in _view_wrapper
    return view_func(request, *args, **kwargs)
  File "/Users/yassineelmoudene/Desktop/Devs/Venv/lib/python3.13/site-packages/rest_framework/viewsets.py", line 125, in view
    return self.dispatch(request, *args, **kwargs)
           ~~~~~~~~~~~~~^^^^^^^^^^^^^^^^^^^^^^^^^^
  File "/Users/yassineelmoudene/Desktop/Devs/Venv/lib/python3.13/site-packages/rest_framework/views.py", line 515, in dispatch
    response = self.handle_exception(exc)
  File "/Users/yassineelmoudene/Desktop/Devs/Venv/lib/python3.13/site-packages/rest_framework/views.py", line 475, in handle_exception
    self.raise_uncaught_exception(exc)
    ~~~~~~~~~~~~~~~~~~~~~~~~~~~~~^^^^^
  File "/Users/yassineelmoudene/Desktop/Devs/Venv/lib/python3.13/site-packages/rest_framework/views.py", line 486, in raise_uncaught_exception
    raise exc
  File "/Users/yassineelmoudene/Desktop/Devs/Venv/lib/python3.13/site-packages/rest_framework/views.py", line 512, in dispatch
    response = handler(request, *args, **kwargs)
  File "/Users/yassineelmoudene/Desktop/Devs/Venv/lib/python3.13/site-packages/rest_framework/mixins.py", line 46, in list
    return Response(serializer.data)
                    ^^^^^^^^^^^^^^^
  File "/Users/yassineelmoudene/Desktop/Devs/Venv/lib/python3.13/site-packages/rest_framework/serializers.py", line 797, in data
    ret = super().data
          ^^^^^^^^^^^^
  File "/Users/yassineelmoudene/Desktop/Devs/Venv/lib/python3.13/site-packages/rest_framework/serializers.py", line 251, in data
    self._data = self.to_representation(self.instance)
                 ~~~~~~~~~~~~~~~~~~~~~~^^^^^^^^^^^^^^^
  File "/Users/yassineelmoudene/Desktop/Devs/Venv/lib/python3.13/site-packages/rest_framework/serializers.py", line 716, in to_representation
    self.child.to_representation(item) for item in iterable
                                                   ^^^^^^^^
  File "/Users/yassineelmoudene/Desktop/Devs/Venv/lib/python3.13/site-packages/django/db/models/query.py", line 400, in __iter__
    self._fetch_all()
    ~~~~~~~~~~~~~~~^^
  File "/Users/yassineelmoudene/Desktop/Devs/Venv/lib/python3.13/site-packages/django/db/models/query.py", line 1928, in _fetch_all
    self._result_cache = list(self._iterable_class(self))
                         ~~~~^^^^^^^^^^^^^^^^^^^^^^^^^^^^
  File "/Users/yassineelmoudene/Desktop/Devs/Venv/lib/python3.13/site-packages/django/db/models/query.py", line 91, in __iter__
    results = compiler.execute_sql(
        chunked_fetch=self.chunked_fetch, chunk_size=self.chunk_size
    )
  File "/Users/yassineelmoudene/Desktop/Devs/Venv/lib/python3.13/site-packages/django/db/models/sql/compiler.py", line 1574, in execute_sql
    cursor.execute(sql, params)
    ~~~~~~~~~~~~~~^^^^^^^^^^^^^
  File "/Users/yassineelmoudene/Desktop/Devs/Venv/lib/python3.13/site-packages/django/db/backends/utils.py", line 122, in execute
    return super().execute(sql, params)
           ~~~~~~~~~~~~~~~^^^^^^^^^^^^^
  File "/Users/yassineelmoudene/Desktop/Devs/Venv/lib/python3.13/site-packages/django/db/backends/utils.py", line 79, in execute
    return self._execute_with_wrappers(
           ~~~~~~~~~~~~~~~~~~~~~~~~~~~^
        sql, params, many=False, executor=self._execute
        ^^^^^^^^^^^^^^^^^^^^^^^^^^^^^^^^^^^^^^^^^^^^^^^
    )
    ^
  File "/Users/yassineelmoudene/Desktop/Devs/Venv/lib/python3.13/site-packages/django/db/backends/utils.py", line 92, in _execute_with_wrappers
    return executor(sql, params, many, context)
  File "/Users/yassineelmoudene/Desktop/Devs/Venv/lib/python3.13/site-packages/django/db/backends/utils.py", line 100, in _execute
    with self.db.wrap_database_errors:
         ^^^^^^^^^^^^^^^^^^^^^^^^^^^^
  File "/Users/yassineelmoudene/Desktop/Devs/Venv/lib/python3.13/site-packages/django/db/utils.py", line 91, in __exit__
    raise dj_exc_value.with_traceback(traceback) from exc_value
  File "/Users/yassineelmoudene/Desktop/Devs/Venv/lib/python3.13/site-packages/django/db/backends/utils.py", line 105, in _execute
    return self.cursor.execute(sql, params)
           ~~~~~~~~~~~~~~~~~~~^^^^^^^^^^^^^
  File "/Users/yassineelmoudene/Desktop/Devs/Venv/lib/python3.13/site-packages/django/db/backends/mysql/base.py", line 76, in execute
    return self.cursor.execute(query, args)
           ~~~~~~~~~~~~~~~~~~~^^^^^^^^^^^^^
  File "/Users/yassineelmoudene/Desktop/Devs/Venv/lib/python3.13/site-packages/MySQLdb/cursors.py", line 179, in execute
    res = self._query(mogrified_query)
  File "/Users/yassineelmoudene/Desktop/Devs/Venv/lib/python3.13/site-packages/MySQLdb/cursors.py", line 330, in _query
    db.query(q)
    ~~~~~~~~^^^
  File "/Users/yassineelmoudene/Desktop/Devs/Venv/lib/python3.13/site-packages/MySQLdb/connections.py", line 261, in query
    _mysql.connection.query(self, query)
    ~~~~~~~~~~~~~~~~~~~~~~~^^^^^^^^^^^^^
django.db.utils.OperationalError: (1054, "Unknown column 'type_client.libelleTypeClient_fr' in 'field list'")
"GET /api/typeclients/ HTTP/1.1" 500 186076
"GET /api/clients/ HTTP/1.1" 200 2
Internal Server Error: /api/typeclients/
Traceback (most recent call last):
  File "/Users/yassineelmoudene/Desktop/Devs/Venv/lib/python3.13/site-packages/django/db/backends/utils.py", line 105, in _execute
    return self.cursor.execute(sql, params)
           ~~~~~~~~~~~~~~~~~~~^^^^^^^^^^^^^
  File "/Users/yassineelmoudene/Desktop/Devs/Venv/lib/python3.13/site-packages/django/db/backends/mysql/base.py", line 76, in execute
    return self.cursor.execute(query, args)
           ~~~~~~~~~~~~~~~~~~~^^^^^^^^^^^^^
  File "/Users/yassineelmoudene/Desktop/Devs/Venv/lib/python3.13/site-packages/MySQLdb/cursors.py", line 179, in execute
    res = self._query(mogrified_query)
  File "/Users/yassineelmoudene/Desktop/Devs/Venv/lib/python3.13/site-packages/MySQLdb/cursors.py", line 330, in _query
    db.query(q)
    ~~~~~~~~^^^
  File "/Users/yassineelmoudene/Desktop/Devs/Venv/lib/python3.13/site-packages/MySQLdb/connections.py", line 261, in query
    _mysql.connection.query(self, query)
    ~~~~~~~~~~~~~~~~~~~~~~~^^^^^^^^^^^^^
MySQLdb.OperationalError: (1054, "Unknown column 'type_client.libelleTypeClient_fr' in 'field list'")

The above exception was the direct cause of the following exception:

Traceback (most recent call last):
  File "/Users/yassineelmoudene/Desktop/Devs/Venv/lib/python3.13/site-packages/django/core/handlers/exception.py", line 55, in inner
    response = get_response(request)
  File "/Users/yassineelmoudene/Desktop/Devs/Venv/lib/python3.13/site-packages/django/core/handlers/base.py", line 197, in _get_response
    response = wrapped_callback(request, *callback_args, **callback_kwargs)
  File "/Users/yassineelmoudene/Desktop/Devs/Venv/lib/python3.13/site-packages/django/views/decorators/csrf.py", line 65, in _view_wrapper
    return view_func(request, *args, **kwargs)
  File "/Users/yassineelmoudene/Desktop/Devs/Venv/lib/python3.13/site-packages/rest_framework/viewsets.py", line 125, in view
    return self.dispatch(request, *args, **kwargs)
           ~~~~~~~~~~~~~^^^^^^^^^^^^^^^^^^^^^^^^^^
  File "/Users/yassineelmoudene/Desktop/Devs/Venv/lib/python3.13/site-packages/rest_framework/views.py", line 515, in dispatch
    response = self.handle_exception(exc)
  File "/Users/yassineelmoudene/Desktop/Devs/Venv/lib/python3.13/site-packages/rest_framework/views.py", line 475, in handle_exception
    self.raise_uncaught_exception(exc)
    ~~~~~~~~~~~~~~~~~~~~~~~~~~~~~^^^^^
  File "/Users/yassineelmoudene/Desktop/Devs/Venv/lib/python3.13/site-packages/rest_framework/views.py", line 486, in raise_uncaught_exception
    raise exc
  File "/Users/yassineelmoudene/Desktop/Devs/Venv/lib/python3.13/site-packages/rest_framework/views.py", line 512, in dispatch
    response = handler(request, *args, **kwargs)
  File "/Users/yassineelmoudene/Desktop/Devs/Venv/lib/python3.13/site-packages/rest_framework/mixins.py", line 46, in list
    return Response(serializer.data)
                    ^^^^^^^^^^^^^^^
  File "/Users/yassineelmoudene/Desktop/Devs/Venv/lib/python3.13/site-packages/rest_framework/serializers.py", line 797, in data
    ret = super().data
          ^^^^^^^^^^^^
  File "/Users/yassineelmoudene/Desktop/Devs/Venv/lib/python3.13/site-packages/rest_framework/serializers.py", line 251, in data
    self._data = self.to_representation(self.instance)
                 ~~~~~~~~~~~~~~~~~~~~~~^^^^^^^^^^^^^^^
  File "/Users/yassineelmoudene/Desktop/Devs/Venv/lib/python3.13/site-packages/rest_framework/serializers.py", line 716, in to_representation
    self.child.to_representation(item) for item in iterable
                                                   ^^^^^^^^
  File "/Users/yassineelmoudene/Desktop/Devs/Venv/lib/python3.13/site-packages/django/db/models/query.py", line 400, in __iter__
    self._fetch_all()
    ~~~~~~~~~~~~~~~^^
  File "/Users/yassineelmoudene/Desktop/Devs/Venv/lib/python3.13/site-packages/django/db/models/query.py", line 1928, in _fetch_all
    self._result_cache = list(self._iterable_class(self))
                         ~~~~^^^^^^^^^^^^^^^^^^^^^^^^^^^^
  File "/Users/yassineelmoudene/Desktop/Devs/Venv/lib/python3.13/site-packages/django/db/models/query.py", line 91, in __iter__
    results = compiler.execute_sql(
        chunked_fetch=self.chunked_fetch, chunk_size=self.chunk_size
    )
  File "/Users/yassineelmoudene/Desktop/Devs/Venv/lib/python3.13/site-packages/django/db/models/sql/compiler.py", line 1574, in execute_sql
    cursor.execute(sql, params)
    ~~~~~~~~~~~~~~^^^^^^^^^^^^^
  File "/Users/yassineelmoudene/Desktop/Devs/Venv/lib/python3.13/site-packages/django/db/backends/utils.py", line 122, in execute
    return super().execute(sql, params)
           ~~~~~~~~~~~~~~~^^^^^^^^^^^^^
  File "/Users/yassineelmoudene/Desktop/Devs/Venv/lib/python3.13/site-packages/django/db/backends/utils.py", line 79, in execute
    return self._execute_with_wrappers(
           ~~~~~~~~~~~~~~~~~~~~~~~~~~~^
        sql, params, many=False, executor=self._execute
        ^^^^^^^^^^^^^^^^^^^^^^^^^^^^^^^^^^^^^^^^^^^^^^^
    )
    ^
  File "/Users/yassineelmoudene/Desktop/Devs/Venv/lib/python3.13/site-packages/django/db/backends/utils.py", line 92, in _execute_with_wrappers
    return executor(sql, params, many, context)
  File "/Users/yassineelmoudene/Desktop/Devs/Venv/lib/python3.13/site-packages/django/db/backends/utils.py", line 100, in _execute
    with self.db.wrap_database_errors:
         ^^^^^^^^^^^^^^^^^^^^^^^^^^^^
  File "/Users/yassineelmoudene/Desktop/Devs/Venv/lib/python3.13/site-packages/django/db/utils.py", line 91, in __exit__
    raise dj_exc_value.with_traceback(traceback) from exc_value
  File "/Users/yassineelmoudene/Desktop/Devs/Venv/lib/python3.13/site-packages/django/db/backends/utils.py", line 105, in _execute
    return self.cursor.execute(sql, params)
           ~~~~~~~~~~~~~~~~~~~^^^^^^^^^^^^^
  File "/Users/yassineelmoudene/Desktop/Devs/Venv/lib/python3.13/site-packages/django/db/backends/mysql/base.py", line 76, in execute
    return self.cursor.execute(query, args)
           ~~~~~~~~~~~~~~~~~~~^^^^^^^^^^^^^
  File "/Users/yassineelmoudene/Desktop/Devs/Venv/lib/python3.13/site-packages/MySQLdb/cursors.py", line 179, in execute
    res = self._query(mogrified_query)
  File "/Users/yassineelmoudene/Desktop/Devs/Venv/lib/python3.13/site-packages/MySQLdb/cursors.py", line 330, in _query
    db.query(q)
    ~~~~~~~~^^^
  File "/Users/yassineelmoudene/Desktop/Devs/Venv/lib/python3.13/site-packages/MySQLdb/connections.py", line 261, in query
    _mysql.connection.query(self, query)
    ~~~~~~~~~~~~~~~~~~~~~~~^^^^^^^^^^^^^
django.db.utils.OperationalError: (1054, "Unknown column 'type_client.libelleTypeClient_fr' in 'field list'")
"GET /api/typeclients/ HTTP/1.1" 500 186074
"GET /api/statutaffaires/ HTTP/1.1" 200 2
"GET /api/clients/ HTTP/1.1" 200 2
"GET /api/fonctionclients/ HTTP/1.1" 200 2
"GET /api/affairejudiciaires/ HTTP/1.1" 200 2
Internal Server Error: /api/typeclients/
Traceback (most recent call last):
  File "/Users/yassineelmoudene/Desktop/Devs/Venv/lib/python3.13/site-packages/django/db/backends/utils.py", line 105, in _execute
    return self.cursor.execute(sql, params)
           ~~~~~~~~~~~~~~~~~~~^^^^^^^^^^^^^
  File "/Users/yassineelmoudene/Desktop/Devs/Venv/lib/python3.13/site-packages/django/db/backends/mysql/base.py", line 76, in execute
    return self.cursor.execute(query, args)
           ~~~~~~~~~~~~~~~~~~~^^^^^^^^^^^^^
  File "/Users/yassineelmoudene/Desktop/Devs/Venv/lib/python3.13/site-packages/MySQLdb/cursors.py", line 179, in execute
    res = self._query(mogrified_query)
  File "/Users/yassineelmoudene/Desktop/Devs/Venv/lib/python3.13/site-packages/MySQLdb/cursors.py", line 330, in _query
    db.query(q)
    ~~~~~~~~^^^
  File "/Users/yassineelmoudene/Desktop/Devs/Venv/lib/python3.13/site-packages/MySQLdb/connections.py", line 261, in query
    _mysql.connection.query(self, query)
    ~~~~~~~~~~~~~~~~~~~~~~~^^^^^^^^^^^^^
MySQLdb.OperationalError: (1054, "Unknown column 'type_client.libelleTypeClient_fr' in 'field list'")

The above exception was the direct cause of the following exception:

Traceback (most recent call last):
  File "/Users/yassineelmoudene/Desktop/Devs/Venv/lib/python3.13/site-packages/django/core/handlers/exception.py", line 55, in inner
    response = get_response(request)
  File "/Users/yassineelmoudene/Desktop/Devs/Venv/lib/python3.13/site-packages/django/core/handlers/base.py", line 197, in _get_response
    response = wrapped_callback(request, *callback_args, **callback_kwargs)
  File "/Users/yassineelmoudene/Desktop/Devs/Venv/lib/python3.13/site-packages/django/views/decorators/csrf.py", line 65, in _view_wrapper
    return view_func(request, *args, **kwargs)
  File "/Users/yassineelmoudene/Desktop/Devs/Venv/lib/python3.13/site-packages/rest_framework/viewsets.py", line 125, in view
    return self.dispatch(request, *args, **kwargs)
           ~~~~~~~~~~~~~^^^^^^^^^^^^^^^^^^^^^^^^^^
  File "/Users/yassineelmoudene/Desktop/Devs/Venv/lib/python3.13/site-packages/rest_framework/views.py", line 515, in dispatch
    response = self.handle_exception(exc)
  File "/Users/yassineelmoudene/Desktop/Devs/Venv/lib/python3.13/site-packages/rest_framework/views.py", line 475, in handle_exception
    self.raise_uncaught_exception(exc)
    ~~~~~~~~~~~~~~~~~~~~~~~~~~~~~^^^^^
  File "/Users/yassineelmoudene/Desktop/Devs/Venv/lib/python3.13/site-packages/rest_framework/views.py", line 486, in raise_uncaught_exception
    raise exc
  File "/Users/yassineelmoudene/Desktop/Devs/Venv/lib/python3.13/site-packages/rest_framework/views.py", line 512, in dispatch
    response = handler(request, *args, **kwargs)
  File "/Users/yassineelmoudene/Desktop/Devs/Venv/lib/python3.13/site-packages/rest_framework/mixins.py", line 46, in list
    return Response(serializer.data)
                    ^^^^^^^^^^^^^^^
  File "/Users/yassineelmoudene/Desktop/Devs/Venv/lib/python3.13/site-packages/rest_framework/serializers.py", line 797, in data
    ret = super().data
          ^^^^^^^^^^^^
  File "/Users/yassineelmoudene/Desktop/Devs/Venv/lib/python3.13/site-packages/rest_framework/serializers.py", line 251, in data
    self._data = self.to_representation(self.instance)
                 ~~~~~~~~~~~~~~~~~~~~~~^^^^^^^^^^^^^^^
  File "/Users/yassineelmoudene/Desktop/Devs/Venv/lib/python3.13/site-packages/rest_framework/serializers.py", line 716, in to_representation
    self.child.to_representation(item) for item in iterable
                                                   ^^^^^^^^
  File "/Users/yassineelmoudene/Desktop/Devs/Venv/lib/python3.13/site-packages/django/db/models/query.py", line 400, in __iter__
    self._fetch_all()
    ~~~~~~~~~~~~~~~^^
  File "/Users/yassineelmoudene/Desktop/Devs/Venv/lib/python3.13/site-packages/django/db/models/query.py", line 1928, in _fetch_all
    self._result_cache = list(self._iterable_class(self))
                         ~~~~^^^^^^^^^^^^^^^^^^^^^^^^^^^^
  File "/Users/yassineelmoudene/Desktop/Devs/Venv/lib/python3.13/site-packages/django/db/models/query.py", line 91, in __iter__
    results = compiler.execute_sql(
        chunked_fetch=self.chunked_fetch, chunk_size=self.chunk_size
    )
  File "/Users/yassineelmoudene/Desktop/Devs/Venv/lib/python3.13/site-packages/django/db/models/sql/compiler.py", line 1574, in execute_sql
    cursor.execute(sql, params)
    ~~~~~~~~~~~~~~^^^^^^^^^^^^^
  File "/Users/yassineelmoudene/Desktop/Devs/Venv/lib/python3.13/site-packages/django/db/backends/utils.py", line 122, in execute
    return super().execute(sql, params)
           ~~~~~~~~~~~~~~~^^^^^^^^^^^^^
  File "/Users/yassineelmoudene/Desktop/Devs/Venv/lib/python3.13/site-packages/django/db/backends/utils.py", line 79, in execute
    return self._execute_with_wrappers(
           ~~~~~~~~~~~~~~~~~~~~~~~~~~~^
        sql, params, many=False, executor=self._execute
        ^^^^^^^^^^^^^^^^^^^^^^^^^^^^^^^^^^^^^^^^^^^^^^^
    )
    ^
  File "/Users/yassineelmoudene/Desktop/Devs/Venv/lib/python3.13/site-packages/django/db/backends/utils.py", line 92, in _execute_with_wrappers
    return executor(sql, params, many, context)
  File "/Users/yassineelmoudene/Desktop/Devs/Venv/lib/python3.13/site-packages/django/db/backends/utils.py", line 100, in _execute
    with self.db.wrap_database_errors:
         ^^^^^^^^^^^^^^^^^^^^^^^^^^^^
  File "/Users/yassineelmoudene/Desktop/Devs/Venv/lib/python3.13/site-packages/django/db/utils.py", line 91, in __exit__
    raise dj_exc_value.with_traceback(traceback) from exc_value
  File "/Users/yassineelmoudene/Desktop/Devs/Venv/lib/python3.13/site-packages/django/db/backends/utils.py", line 105, in _execute
    return self.cursor.execute(sql, params)
           ~~~~~~~~~~~~~~~~~~~^^^^^^^^^^^^^
  File "/Users/yassineelmoudene/Desktop/Devs/Venv/lib/python3.13/site-packages/django/db/backends/mysql/base.py", line 76, in execute
    return self.cursor.execute(query, args)
           ~~~~~~~~~~~~~~~~~~~^^^^^^^^^^^^^
  File "/Users/yassineelmoudene/Desktop/Devs/Venv/lib/python3.13/site-packages/MySQLdb/cursors.py", line 179, in execute
    res = self._query(mogrified_query)
  File "/Users/yassineelmoudene/Desktop/Devs/Venv/lib/python3.13/site-packages/MySQLdb/cursors.py", line 330, in _query
    db.query(q)
    ~~~~~~~~^^^
  File "/Users/yassineelmoudene/Desktop/Devs/Venv/lib/python3.13/site-packages/MySQLdb/connections.py", line 261, in query
    _mysql.connection.query(self, query)
    ~~~~~~~~~~~~~~~~~~~~~~~^^^^^^^^^^^^^
django.db.utils.OperationalError: (1054, "Unknown column 'type_client.libelleTypeClient_fr' in 'field list'")
Internal Server Error: /api/typeaffaires/
Traceback (most recent call last):
  File "/Users/yassineelmoudene/Desktop/Devs/Venv/lib/python3.13/site-packages/django/db/backends/utils.py", line 105, in _execute
    return self.cursor.execute(sql, params)
           ~~~~~~~~~~~~~~~~~~~^^^^^^^^^^^^^
  File "/Users/yassineelmoudene/Desktop/Devs/Venv/lib/python3.13/site-packages/django/db/backends/mysql/base.py", line 76, in execute
    return self.cursor.execute(query, args)
           ~~~~~~~~~~~~~~~~~~~^^^^^^^^^^^^^
  File "/Users/yassineelmoudene/Desktop/Devs/Venv/lib/python3.13/site-packages/MySQLdb/cursors.py", line 179, in execute
    res = self._query(mogrified_query)
  File "/Users/yassineelmoudene/Desktop/Devs/Venv/lib/python3.13/site-packages/MySQLdb/cursors.py", line 330, in _query
    db.query(q)
    ~~~~~~~~^^^
  File "/Users/yassineelmoudene/Desktop/Devs/Venv/lib/python3.13/site-packages/MySQLdb/connections.py", line 261, in query
    _mysql.connection.query(self, query)
    ~~~~~~~~~~~~~~~~~~~~~~~^^^^^^^^^^^^^
MySQLdb.OperationalError: (1054, "Unknown column 'type_affaire.libelleTypeAffaire_fr' in 'field list'")

The above exception was the direct cause of the following exception:

Traceback (most recent call last):
  File "/Users/yassineelmoudene/Desktop/Devs/Venv/lib/python3.13/site-packages/django/core/handlers/exception.py", line 55, in inner
    response = get_response(request)
  File "/Users/yassineelmoudene/Desktop/Devs/Venv/lib/python3.13/site-packages/django/core/handlers/base.py", line 197, in _get_response
    response = wrapped_callback(request, *callback_args, **callback_kwargs)
  File "/Users/yassineelmoudene/Desktop/Devs/Venv/lib/python3.13/site-packages/django/views/decorators/csrf.py", line 65, in _view_wrapper
    return view_func(request, *args, **kwargs)
  File "/Users/yassineelmoudene/Desktop/Devs/Venv/lib/python3.13/site-packages/rest_framework/viewsets.py", line 125, in view
    return self.dispatch(request, *args, **kwargs)
           ~~~~~~~~~~~~~^^^^^^^^^^^^^^^^^^^^^^^^^^
  File "/Users/yassineelmoudene/Desktop/Devs/Venv/lib/python3.13/site-packages/rest_framework/views.py", line 515, in dispatch
    response = self.handle_exception(exc)
  File "/Users/yassineelmoudene/Desktop/Devs/Venv/lib/python3.13/site-packages/rest_framework/views.py", line 475, in handle_exception
    self.raise_uncaught_exception(exc)
    ~~~~~~~~~~~~~~~~~~~~~~~~~~~~~^^^^^
  File "/Users/yassineelmoudene/Desktop/Devs/Venv/lib/python3.13/site-packages/rest_framework/views.py", line 486, in raise_uncaught_exception
    raise exc
  File "/Users/yassineelmoudene/Desktop/Devs/Venv/lib/python3.13/site-packages/rest_framework/views.py", line 512, in dispatch
    response = handler(request, *args, **kwargs)
  File "/Users/yassineelmoudene/Desktop/Devs/Venv/lib/python3.13/site-packages/rest_framework/mixins.py", line 46, in list
    return Response(serializer.data)
                    ^^^^^^^^^^^^^^^
  File "/Users/yassineelmoudene/Desktop/Devs/Venv/lib/python3.13/site-packages/rest_framework/serializers.py", line 797, in data
    ret = super().data
          ^^^^^^^^^^^^
  File "/Users/yassineelmoudene/Desktop/Devs/Venv/lib/python3.13/site-packages/rest_framework/serializers.py", line 251, in data
    self._data = self.to_representation(self.instance)
                 ~~~~~~~~~~~~~~~~~~~~~~^^^^^^^^^^^^^^^
  File "/Users/yassineelmoudene/Desktop/Devs/Venv/lib/python3.13/site-packages/rest_framework/serializers.py", line 716, in to_representation
    self.child.to_representation(item) for item in iterable
                                                   ^^^^^^^^
  File "/Users/yassineelmoudene/Desktop/Devs/Venv/lib/python3.13/site-packages/django/db/models/query.py", line 400, in __iter__
    self._fetch_all()
    ~~~~~~~~~~~~~~~^^
  File "/Users/yassineelmoudene/Desktop/Devs/Venv/lib/python3.13/site-packages/django/db/models/query.py", line 1928, in _fetch_all
    self._result_cache = list(self._iterable_class(self))
                         ~~~~^^^^^^^^^^^^^^^^^^^^^^^^^^^^
  File "/Users/yassineelmoudene/Desktop/Devs/Venv/lib/python3.13/site-packages/django/db/models/query.py", line 91, in __iter__
    results = compiler.execute_sql(
        chunked_fetch=self.chunked_fetch, chunk_size=self.chunk_size
    )
  File "/Users/yassineelmoudene/Desktop/Devs/Venv/lib/python3.13/site-packages/django/db/models/sql/compiler.py", line 1574, in execute_sql
    cursor.execute(sql, params)
    ~~~~~~~~~~~~~~^^^^^^^^^^^^^
  File "/Users/yassineelmoudene/Desktop/Devs/Venv/lib/python3.13/site-packages/django/db/backends/utils.py", line 122, in execute
    return super().execute(sql, params)
           ~~~~~~~~~~~~~~~^^^^^^^^^^^^^
  File "/Users/yassineelmoudene/Desktop/Devs/Venv/lib/python3.13/site-packages/django/db/backends/utils.py", line 79, in execute
    return self._execute_with_wrappers(
           ~~~~~~~~~~~~~~~~~~~~~~~~~~~^
        sql, params, many=False, executor=self._execute
        ^^^^^^^^^^^^^^^^^^^^^^^^^^^^^^^^^^^^^^^^^^^^^^^
    )
    ^
  File "/Users/yassineelmoudene/Desktop/Devs/Venv/lib/python3.13/site-packages/django/db/backends/utils.py", line 92, in _execute_with_wrappers
    return executor(sql, params, many, context)
  File "/Users/yassineelmoudene/Desktop/Devs/Venv/lib/python3.13/site-packages/django/db/backends/utils.py", line 100, in _execute
    with self.db.wrap_database_errors:
         ^^^^^^^^^^^^^^^^^^^^^^^^^^^^
  File "/Users/yassineelmoudene/Desktop/Devs/Venv/lib/python3.13/site-packages/django/db/utils.py", line 91, in __exit__
    raise dj_exc_value.with_traceback(traceback) from exc_value
  File "/Users/yassineelmoudene/Desktop/Devs/Venv/lib/python3.13/site-packages/django/db/backends/utils.py", line 105, in _execute
    return self.cursor.execute(sql, params)
           ~~~~~~~~~~~~~~~~~~~^^^^^^^^^^^^^
  File "/Users/yassineelmoudene/Desktop/Devs/Venv/lib/python3.13/site-packages/django/db/backends/mysql/base.py", line 76, in execute
    return self.cursor.execute(query, args)
           ~~~~~~~~~~~~~~~~~~~^^^^^^^^^^^^^
  File "/Users/yassineelmoudene/Desktop/Devs/Venv/lib/python3.13/site-packages/MySQLdb/cursors.py", line 179, in execute
    res = self._query(mogrified_query)
  File "/Users/yassineelmoudene/Desktop/Devs/Venv/lib/python3.13/site-packages/MySQLdb/cursors.py", line 330, in _query
    db.query(q)
    ~~~~~~~~^^^
  File "/Users/yassineelmoudene/Desktop/Devs/Venv/lib/python3.13/site-packages/MySQLdb/connections.py", line 261, in query
    _mysql.connection.query(self, query)
    ~~~~~~~~~~~~~~~~~~~~~~~^^^^^^^^^^^^^
django.db.utils.OperationalError: (1054, "Unknown column 'type_affaire.libelleTypeAffaire_fr' in 'field list'")
"GET /api/typeclients/ HTTP/1.1" 500 186075
"GET /api/typeaffaires/ HTTP/1.1" 500 186422
/Users/yassineelmoudene/Desktop/Devs/avocat_web/api/models.py changed, reloading.
Watching for file changes with StatReloader
code 400, message Bad request version ("\x06¨\x00v\x13\x02\x13\x03\x13\x01À/À+À0À,\x00\x9eÀ'\x00gÀ(\x00k\x00£\x00\x9fÌ©Ì¨ÌªÀ¯À\xadÀ£À\x9fÀ]ÀaÀWÀS\x00¢À®À¬À¢À\x9eÀ\\À`ÀVÀRÀ$\x00jÀ#\x00@À")
code 400, message Bad request version ("\x00v\x13\x02\x13\x03\x13\x01À/À+À0À,\x00\x9eÀ'\x00gÀ(\x00k\x00£\x00\x9fÌ©Ì¨ÌªÀ¯À\xadÀ£À\x9fÀ]ÀaÀWÀS\x00¢À®À¬À¢À\x9eÀ\\À`ÀVÀRÀ$\x00jÀ#\x00@À")
code 400, message Bad request version ("\x00v\x13\x02\x13\x03\x13\x01À/À+À0À,\x00\x9eÀ'\x00gÀ(\x00k\x00£\x00\x9fÌ©Ì¨ÌªÀ¯À\xadÀ£À\x9fÀ]ÀaÀWÀS\x00¢À®À¬À¢À\x9eÀ\\À`ÀVÀRÀ$\x00jÀ#\x00@À")
code 400, message Bad request version ("ökJ°h\x0fh\x86²}}q\x91P\x07y\x9a°\x83LàÌ§\x085è\x8c\x97\x88¯\x84j\x00v\x13\x02\x13\x03\x13\x01À/À+À0À,\x00\x9eÀ'\x00gÀ(\x00k\x00£\x00\x9fÌ©Ì¨ÌªÀ¯À\xadÀ£À\x9fÀ]ÀaÀWÀS\x00¢À®À¬À¢À\x9eÀ\\À`ÀVÀRÀ$\x00jÀ#\x00@À")
You're accessing the development server over HTTPS, but it only supports HTTP.
code 400, message Bad request version (",\x17+\x00v\x13\x02\x13\x03\x13\x01À/À+À0À,\x00\x9eÀ'\x00gÀ(\x00k\x00£\x00\x9fÌ©Ì¨ÌªÀ¯À\xadÀ£À\x9fÀ]ÀaÀWÀS\x00¢À®À¬À¢À\x9eÀ\\À`ÀVÀRÀ$\x00jÀ#\x00@À")
code 400, message Bad request version ('+«ç9÷\x96":\x00v\x13\x02\x13\x03\x13\x01À/À+À0À,\x00\x9eÀ\'\x00gÀ(\x00k\x00£\x00\x9fÌ©Ì¨ÌªÀ¯À\xadÀ£À\x9fÀ]ÀaÀWÀS\x00¢À®À¬À¢À\x9eÀ\\À`ÀVÀRÀ$\x00jÀ#\x00@À')
You're accessing the development server over HTTPS, but it only supports HTTP.
You're accessing the development server over HTTPS, but it only supports HTTP.
You're accessing the development server over HTTPS, but it only supports HTTP.
You're accessing the development server over HTTPS, but it only supports HTTP.
You're accessing the development server over HTTPS, but it only supports HTTP.
code 400, message Bad request version ("mL\x00v\x13\x02\x13\x03\x13\x01À/À+À0À,\x00\x9eÀ'\x00gÀ(\x00k\x00£\x00\x9fÌ©Ì¨ÌªÀ¯À\xadÀ£À\x9fÀ]ÀaÀWÀS\x00¢À®À¬À¢À\x9eÀ\\À`ÀVÀRÀ$\x00jÀ#\x00@À")
code 400, message Bad request version ("\x89Kzï¢\x9aNáp³\x13V²\xad]\x08¡\xad\x00v\x13\x02\x13\x03\x13\x01À/À+À0À,\x00\x9eÀ'\x00gÀ(\x00k\x00£\x00\x9fÌ©Ì¨ÌªÀ¯À\xadÀ£À\x9fÀ]ÀaÀWÀS\x00¢À®À¬À¢À\x9eÀ\\À`ÀVÀRÀ$\x00jÀ#\x00@À")
code 400, message Bad request version ("\x04\\\x13æ¢\x87\x8e¹C\x89^!\x94÷\x06·©î1beÌÑ)-9{\x81þ#\x06d\x00v\x13\x02\x13\x03\x13\x01À/À+À0À,\x00\x9eÀ'\x00gÀ(\x00k\x00£\x00\x9fÌ©Ì¨ÌªÀ¯À\xadÀ£À\x9fÀ]ÀaÀWÀS\x00¢À®À¬À¢À\x9eÀ\\À`ÀVÀRÀ$\x00jÀ#\x00@À")
You're accessing the development server over HTTPS, but it only supports HTTP.
code 400, message Bad request version ("H\x8c[±v\x08å\x9dÜã\x11Qã\x8a\x1b\x1b¯v\x16Í\x91\xad\x0f°+iù\x00v\x13\x02\x13\x03\x13\x01À/À+À0À,\x00\x9eÀ'\x00gÀ(\x00k\x00£\x00\x9fÌ©Ì¨ÌªÀ¯À\xadÀ£À\x9fÀ]ÀaÀWÀS\x00¢À®À¬À¢À\x9eÀ\\À`ÀVÀRÀ$\x00jÀ#\x00@À")
You're accessing the development server over HTTPS, but it only supports HTTP.
You're accessing the development server over HTTPS, but it only supports HTTP.
code 400, message Bad request version ('\x17»"\x00v\x13\x02\x13\x03\x13\x01À/À+À0À,\x00\x9eÀ\'\x00gÀ(\x00k\x00£\x00\x9fÌ©Ì¨ÌªÀ¯À\xadÀ£À\x9fÀ]ÀaÀWÀS\x00¢À®À¬À¢À\x9eÀ\\À`ÀVÀRÀ$\x00jÀ#\x00@À')
You're accessing the development server over HTTPS, but it only supports HTTP.
code 400, message Bad request version ("Í\x8aI¦,¢ø¦Ú§[üê9t\x00v\x13\x02\x13\x03\x13\x01À/À+À0À,\x00\x9eÀ'\x00gÀ(\x00k\x00£\x00\x9fÌ©Ì¨ÌªÀ¯À\xadÀ£À\x9fÀ]ÀaÀWÀS\x00¢À®À¬À¢À\x9eÀ\\À`ÀVÀRÀ$\x00jÀ#\x00@À")
You're accessing the development server over HTTPS, but it only supports HTTP.
You're accessing the development server over HTTPS, but it only supports HTTP.
"GET /api/clients/ HTTP/1.1" 200 2
"GET /api/fonctionclients/ HTTP/1.1" 200 2
"GET /api/affairejudiciaires/ HTTP/1.1" 200 2
"GET /api/statutaffaires/ HTTP/1.1" 200 2
Internal Server Error: /api/typeaffaires/
Traceback (most recent call last):
  File "/Users/yassineelmoudene/Desktop/Devs/Venv/lib/python3.13/site-packages/django/db/backends/utils.py", line 105, in _execute
    return self.cursor.execute(sql, params)
           ~~~~~~~~~~~~~~~~~~~^^^^^^^^^^^^^
  File "/Users/yassineelmoudene/Desktop/Devs/Venv/lib/python3.13/site-packages/django/db/backends/mysql/base.py", line 76, in execute
    return self.cursor.execute(query, args)
           ~~~~~~~~~~~~~~~~~~~^^^^^^^^^^^^^
  File "/Users/yassineelmoudene/Desktop/Devs/Venv/lib/python3.13/site-packages/MySQLdb/cursors.py", line 179, in execute
    res = self._query(mogrified_query)
  File "/Users/yassineelmoudene/Desktop/Devs/Venv/lib/python3.13/site-packages/MySQLdb/cursors.py", line 330, in _query
    db.query(q)
    ~~~~~~~~^^^
  File "/Users/yassineelmoudene/Desktop/Devs/Venv/lib/python3.13/site-packages/MySQLdb/connections.py", line 261, in query
    _mysql.connection.query(self, query)
    ~~~~~~~~~~~~~~~~~~~~~~~^^^^^^^^^^^^^
MySQLdb.OperationalError: (1054, "Unknown column 'type_affaire.libelleTypeAffaire_fr' in 'field list'")

The above exception was the direct cause of the following exception:

Traceback (most recent call last):
  File "/Users/yassineelmoudene/Desktop/Devs/Venv/lib/python3.13/site-packages/django/core/handlers/exception.py", line 55, in inner
    response = get_response(request)
  File "/Users/yassineelmoudene/Desktop/Devs/Venv/lib/python3.13/site-packages/django/core/handlers/base.py", line 197, in _get_response
    response = wrapped_callback(request, *callback_args, **callback_kwargs)
  File "/Users/yassineelmoudene/Desktop/Devs/Venv/lib/python3.13/site-packages/django/views/decorators/csrf.py", line 65, in _view_wrapper
    return view_func(request, *args, **kwargs)
  File "/Users/yassineelmoudene/Desktop/Devs/Venv/lib/python3.13/site-packages/rest_framework/viewsets.py", line 125, in view
    return self.dispatch(request, *args, **kwargs)
           ~~~~~~~~~~~~~^^^^^^^^^^^^^^^^^^^^^^^^^^
  File "/Users/yassineelmoudene/Desktop/Devs/Venv/lib/python3.13/site-packages/rest_framework/views.py", line 515, in dispatch
    response = self.handle_exception(exc)
  File "/Users/yassineelmoudene/Desktop/Devs/Venv/lib/python3.13/site-packages/rest_framework/views.py", line 475, in handle_exception
    self.raise_uncaught_exception(exc)
    ~~~~~~~~~~~~~~~~~~~~~~~~~~~~~^^^^^
  File "/Users/yassineelmoudene/Desktop/Devs/Venv/lib/python3.13/site-packages/rest_framework/views.py", line 486, in raise_uncaught_exception
    raise exc
  File "/Users/yassineelmoudene/Desktop/Devs/Venv/lib/python3.13/site-packages/rest_framework/views.py", line 512, in dispatch
    response = handler(request, *args, **kwargs)
  File "/Users/yassineelmoudene/Desktop/Devs/Venv/lib/python3.13/site-packages/rest_framework/mixins.py", line 46, in list
    return Response(serializer.data)
                    ^^^^^^^^^^^^^^^
  File "/Users/yassineelmoudene/Desktop/Devs/Venv/lib/python3.13/site-packages/rest_framework/serializers.py", line 797, in data
    ret = super().data
          ^^^^^^^^^^^^
  File "/Users/yassineelmoudene/Desktop/Devs/Venv/lib/python3.13/site-packages/rest_framework/serializers.py", line 251, in data
    self._data = self.to_representation(self.instance)
                 ~~~~~~~~~~~~~~~~~~~~~~^^^^^^^^^^^^^^^
  File "/Users/yassineelmoudene/Desktop/Devs/Venv/lib/python3.13/site-packages/rest_framework/serializers.py", line 716, in to_representation
    self.child.to_representation(item) for item in iterable
                                                   ^^^^^^^^
  File "/Users/yassineelmoudene/Desktop/Devs/Venv/lib/python3.13/site-packages/django/db/models/query.py", line 400, in __iter__
    self._fetch_all()
    ~~~~~~~~~~~~~~~^^
  File "/Users/yassineelmoudene/Desktop/Devs/Venv/lib/python3.13/site-packages/django/db/models/query.py", line 1928, in _fetch_all
    self._result_cache = list(self._iterable_class(self))
                         ~~~~^^^^^^^^^^^^^^^^^^^^^^^^^^^^
  File "/Users/yassineelmoudene/Desktop/Devs/Venv/lib/python3.13/site-packages/django/db/models/query.py", line 91, in __iter__
    results = compiler.execute_sql(
        chunked_fetch=self.chunked_fetch, chunk_size=self.chunk_size
    )
  File "/Users/yassineelmoudene/Desktop/Devs/Venv/lib/python3.13/site-packages/django/db/models/sql/compiler.py", line 1574, in execute_sql
    cursor.execute(sql, params)
    ~~~~~~~~~~~~~~^^^^^^^^^^^^^
  File "/Users/yassineelmoudene/Desktop/Devs/Venv/lib/python3.13/site-packages/django/db/backends/utils.py", line 122, in execute
    return super().execute(sql, params)
           ~~~~~~~~~~~~~~~^^^^^^^^^^^^^
  File "/Users/yassineelmoudene/Desktop/Devs/Venv/lib/python3.13/site-packages/django/db/backends/utils.py", line 79, in execute
    return self._execute_with_wrappers(
           ~~~~~~~~~~~~~~~~~~~~~~~~~~~^
        sql, params, many=False, executor=self._execute
        ^^^^^^^^^^^^^^^^^^^^^^^^^^^^^^^^^^^^^^^^^^^^^^^
    )
    ^
  File "/Users/yassineelmoudene/Desktop/Devs/Venv/lib/python3.13/site-packages/django/db/backends/utils.py", line 92, in _execute_with_wrappers
    return executor(sql, params, many, context)
  File "/Users/yassineelmoudene/Desktop/Devs/Venv/lib/python3.13/site-packages/django/db/backends/utils.py", line 100, in _execute
    with self.db.wrap_database_errors:
         ^^^^^^^^^^^^^^^^^^^^^^^^^^^^
  File "/Users/yassineelmoudene/Desktop/Devs/Venv/lib/python3.13/site-packages/django/db/utils.py", line 91, in __exit__
    raise dj_exc_value.with_traceback(traceback) from exc_value
  File "/Users/yassineelmoudene/Desktop/Devs/Venv/lib/python3.13/site-packages/django/db/backends/utils.py", line 105, in _execute
    return self.cursor.execute(sql, params)
           ~~~~~~~~~~~~~~~~~~~^^^^^^^^^^^^^
  File "/Users/yassineelmoudene/Desktop/Devs/Venv/lib/python3.13/site-packages/django/db/backends/mysql/base.py", line 76, in execute
    return self.cursor.execute(query, args)
           ~~~~~~~~~~~~~~~~~~~^^^^^^^^^^^^^
  File "/Users/yassineelmoudene/Desktop/Devs/Venv/lib/python3.13/site-packages/MySQLdb/cursors.py", line 179, in execute
    res = self._query(mogrified_query)
  File "/Users/yassineelmoudene/Desktop/Devs/Venv/lib/python3.13/site-packages/MySQLdb/cursors.py", line 330, in _query
    db.query(q)
    ~~~~~~~~^^^
  File "/Users/yassineelmoudene/Desktop/Devs/Venv/lib/python3.13/site-packages/MySQLdb/connections.py", line 261, in query
    _mysql.connection.query(self, query)
    ~~~~~~~~~~~~~~~~~~~~~~~^^^^^^^^^^^^^
django.db.utils.OperationalError: (1054, "Unknown column 'type_affaire.libelleTypeAffaire_fr' in 'field list'")
Internal Server Error: /api/typeclients/
Traceback (most recent call last):
  File "/Users/yassineelmoudene/Desktop/Devs/Venv/lib/python3.13/site-packages/django/db/backends/utils.py", line 105, in _execute
    return self.cursor.execute(sql, params)
           ~~~~~~~~~~~~~~~~~~~^^^^^^^^^^^^^
  File "/Users/yassineelmoudene/Desktop/Devs/Venv/lib/python3.13/site-packages/django/db/backends/mysql/base.py", line 76, in execute
    return self.cursor.execute(query, args)
           ~~~~~~~~~~~~~~~~~~~^^^^^^^^^^^^^
  File "/Users/yassineelmoudene/Desktop/Devs/Venv/lib/python3.13/site-packages/MySQLdb/cursors.py", line 179, in execute
    res = self._query(mogrified_query)
  File "/Users/yassineelmoudene/Desktop/Devs/Venv/lib/python3.13/site-packages/MySQLdb/cursors.py", line 330, in _query
    db.query(q)
    ~~~~~~~~^^^
  File "/Users/yassineelmoudene/Desktop/Devs/Venv/lib/python3.13/site-packages/MySQLdb/connections.py", line 261, in query
    _mysql.connection.query(self, query)
    ~~~~~~~~~~~~~~~~~~~~~~~^^^^^^^^^^^^^
MySQLdb.OperationalError: (1054, "Unknown column 'type_client.libelleTypeClient_fr' in 'field list'")

The above exception was the direct cause of the following exception:

Traceback (most recent call last):
  File "/Users/yassineelmoudene/Desktop/Devs/Venv/lib/python3.13/site-packages/django/core/handlers/exception.py", line 55, in inner
    response = get_response(request)
  File "/Users/yassineelmoudene/Desktop/Devs/Venv/lib/python3.13/site-packages/django/core/handlers/base.py", line 197, in _get_response
    response = wrapped_callback(request, *callback_args, **callback_kwargs)
  File "/Users/yassineelmoudene/Desktop/Devs/Venv/lib/python3.13/site-packages/django/views/decorators/csrf.py", line 65, in _view_wrapper
    return view_func(request, *args, **kwargs)
  File "/Users/yassineelmoudene/Desktop/Devs/Venv/lib/python3.13/site-packages/rest_framework/viewsets.py", line 125, in view
    return self.dispatch(request, *args, **kwargs)
           ~~~~~~~~~~~~~^^^^^^^^^^^^^^^^^^^^^^^^^^
  File "/Users/yassineelmoudene/Desktop/Devs/Venv/lib/python3.13/site-packages/rest_framework/views.py", line 515, in dispatch
    response = self.handle_exception(exc)
  File "/Users/yassineelmoudene/Desktop/Devs/Venv/lib/python3.13/site-packages/rest_framework/views.py", line 475, in handle_exception
    self.raise_uncaught_exception(exc)
    ~~~~~~~~~~~~~~~~~~~~~~~~~~~~~^^^^^
  File "/Users/yassineelmoudene/Desktop/Devs/Venv/lib/python3.13/site-packages/rest_framework/views.py", line 486, in raise_uncaught_exception
    raise exc
  File "/Users/yassineelmoudene/Desktop/Devs/Venv/lib/python3.13/site-packages/rest_framework/views.py", line 512, in dispatch
    response = handler(request, *args, **kwargs)
  File "/Users/yassineelmoudene/Desktop/Devs/Venv/lib/python3.13/site-packages/rest_framework/mixins.py", line 46, in list
    return Response(serializer.data)
                    ^^^^^^^^^^^^^^^
  File "/Users/yassineelmoudene/Desktop/Devs/Venv/lib/python3.13/site-packages/rest_framework/serializers.py", line 797, in data
    ret = super().data
          ^^^^^^^^^^^^
  File "/Users/yassineelmoudene/Desktop/Devs/Venv/lib/python3.13/site-packages/rest_framework/serializers.py", line 251, in data
    self._data = self.to_representation(self.instance)
                 ~~~~~~~~~~~~~~~~~~~~~~^^^^^^^^^^^^^^^
  File "/Users/yassineelmoudene/Desktop/Devs/Venv/lib/python3.13/site-packages/rest_framework/serializers.py", line 716, in to_representation
    self.child.to_representation(item) for item in iterable
                                                   ^^^^^^^^
  File "/Users/yassineelmoudene/Desktop/Devs/Venv/lib/python3.13/site-packages/django/db/models/query.py", line 400, in __iter__
    self._fetch_all()
    ~~~~~~~~~~~~~~~^^
  File "/Users/yassineelmoudene/Desktop/Devs/Venv/lib/python3.13/site-packages/django/db/models/query.py", line 1928, in _fetch_all
    self._result_cache = list(self._iterable_class(self))
                         ~~~~^^^^^^^^^^^^^^^^^^^^^^^^^^^^
  File "/Users/yassineelmoudene/Desktop/Devs/Venv/lib/python3.13/site-packages/django/db/models/query.py", line 91, in __iter__
    results = compiler.execute_sql(
        chunked_fetch=self.chunked_fetch, chunk_size=self.chunk_size
    )
  File "/Users/yassineelmoudene/Desktop/Devs/Venv/lib/python3.13/site-packages/django/db/models/sql/compiler.py", line 1574, in execute_sql
    cursor.execute(sql, params)
    ~~~~~~~~~~~~~~^^^^^^^^^^^^^
  File "/Users/yassineelmoudene/Desktop/Devs/Venv/lib/python3.13/site-packages/django/db/backends/utils.py", line 122, in execute
    return super().execute(sql, params)
           ~~~~~~~~~~~~~~~^^^^^^^^^^^^^
  File "/Users/yassineelmoudene/Desktop/Devs/Venv/lib/python3.13/site-packages/django/db/backends/utils.py", line 79, in execute
    return self._execute_with_wrappers(
           ~~~~~~~~~~~~~~~~~~~~~~~~~~~^
        sql, params, many=False, executor=self._execute
        ^^^^^^^^^^^^^^^^^^^^^^^^^^^^^^^^^^^^^^^^^^^^^^^
    )
    ^
  File "/Users/yassineelmoudene/Desktop/Devs/Venv/lib/python3.13/site-packages/django/db/backends/utils.py", line 92, in _execute_with_wrappers
    return executor(sql, params, many, context)
  File "/Users/yassineelmoudene/Desktop/Devs/Venv/lib/python3.13/site-packages/django/db/backends/utils.py", line 100, in _execute
    with self.db.wrap_database_errors:
         ^^^^^^^^^^^^^^^^^^^^^^^^^^^^
  File "/Users/yassineelmoudene/Desktop/Devs/Venv/lib/python3.13/site-packages/django/db/utils.py", line 91, in __exit__
    raise dj_exc_value.with_traceback(traceback) from exc_value
  File "/Users/yassineelmoudene/Desktop/Devs/Venv/lib/python3.13/site-packages/django/db/backends/utils.py", line 105, in _execute
    return self.cursor.execute(sql, params)
           ~~~~~~~~~~~~~~~~~~~^^^^^^^^^^^^^
  File "/Users/yassineelmoudene/Desktop/Devs/Venv/lib/python3.13/site-packages/django/db/backends/mysql/base.py", line 76, in execute
    return self.cursor.execute(query, args)
           ~~~~~~~~~~~~~~~~~~~^^^^^^^^^^^^^
  File "/Users/yassineelmoudene/Desktop/Devs/Venv/lib/python3.13/site-packages/MySQLdb/cursors.py", line 179, in execute
    res = self._query(mogrified_query)
  File "/Users/yassineelmoudene/Desktop/Devs/Venv/lib/python3.13/site-packages/MySQLdb/cursors.py", line 330, in _query
    db.query(q)
    ~~~~~~~~^^^
  File "/Users/yassineelmoudene/Desktop/Devs/Venv/lib/python3.13/site-packages/MySQLdb/connections.py", line 261, in query
    _mysql.connection.query(self, query)
    ~~~~~~~~~~~~~~~~~~~~~~~^^^^^^^^^^^^^
django.db.utils.OperationalError: (1054, "Unknown column 'type_client.libelleTypeClient_fr' in 'field list'")
"GET /api/typeaffaires/ HTTP/1.1" 500 186422
"GET /api/typeclients/ HTTP/1.1" 500 186075
"GET /api/fonctionclients/ HTTP/1.1" 200 2
Internal Server Error: /api/typeclients/
Traceback (most recent call last):
  File "/Users/yassineelmoudene/Desktop/Devs/Venv/lib/python3.13/site-packages/django/db/backends/utils.py", line 105, in _execute
    return self.cursor.execute(sql, params)
           ~~~~~~~~~~~~~~~~~~~^^^^^^^^^^^^^
  File "/Users/yassineelmoudene/Desktop/Devs/Venv/lib/python3.13/site-packages/django/db/backends/mysql/base.py", line 76, in execute
    return self.cursor.execute(query, args)
           ~~~~~~~~~~~~~~~~~~~^^^^^^^^^^^^^
  File "/Users/yassineelmoudene/Desktop/Devs/Venv/lib/python3.13/site-packages/MySQLdb/cursors.py", line 179, in execute
    res = self._query(mogrified_query)
  File "/Users/yassineelmoudene/Desktop/Devs/Venv/lib/python3.13/site-packages/MySQLdb/cursors.py", line 330, in _query
    db.query(q)
    ~~~~~~~~^^^
  File "/Users/yassineelmoudene/Desktop/Devs/Venv/lib/python3.13/site-packages/MySQLdb/connections.py", line 261, in query
    _mysql.connection.query(self, query)
    ~~~~~~~~~~~~~~~~~~~~~~~^^^^^^^^^^^^^
MySQLdb.OperationalError: (1054, "Unknown column 'type_client.libelleTypeClient_fr' in 'field list'")

The above exception was the direct cause of the following exception:

Traceback (most recent call last):
  File "/Users/yassineelmoudene/Desktop/Devs/Venv/lib/python3.13/site-packages/django/core/handlers/exception.py", line 55, in inner
    response = get_response(request)
  File "/Users/yassineelmoudene/Desktop/Devs/Venv/lib/python3.13/site-packages/django/core/handlers/base.py", line 197, in _get_response
    response = wrapped_callback(request, *callback_args, **callback_kwargs)
  File "/Users/yassineelmoudene/Desktop/Devs/Venv/lib/python3.13/site-packages/django/views/decorators/csrf.py", line 65, in _view_wrapper
    return view_func(request, *args, **kwargs)
  File "/Users/yassineelmoudene/Desktop/Devs/Venv/lib/python3.13/site-packages/rest_framework/viewsets.py", line 125, in view
    return self.dispatch(request, *args, **kwargs)
           ~~~~~~~~~~~~~^^^^^^^^^^^^^^^^^^^^^^^^^^
  File "/Users/yassineelmoudene/Desktop/Devs/Venv/lib/python3.13/site-packages/rest_framework/views.py", line 515, in dispatch
    response = self.handle_exception(exc)
  File "/Users/yassineelmoudene/Desktop/Devs/Venv/lib/python3.13/site-packages/rest_framework/views.py", line 475, in handle_exception
    self.raise_uncaught_exception(exc)
    ~~~~~~~~~~~~~~~~~~~~~~~~~~~~~^^^^^
  File "/Users/yassineelmoudene/Desktop/Devs/Venv/lib/python3.13/site-packages/rest_framework/views.py", line 486, in raise_uncaught_exception
    raise exc
  File "/Users/yassineelmoudene/Desktop/Devs/Venv/lib/python3.13/site-packages/rest_framework/views.py", line 512, in dispatch
    response = handler(request, *args, **kwargs)
  File "/Users/yassineelmoudene/Desktop/Devs/Venv/lib/python3.13/site-packages/rest_framework/mixins.py", line 46, in list
    return Response(serializer.data)
                    ^^^^^^^^^^^^^^^
  File "/Users/yassineelmoudene/Desktop/Devs/Venv/lib/python3.13/site-packages/rest_framework/serializers.py", line 797, in data
    ret = super().data
          ^^^^^^^^^^^^
  File "/Users/yassineelmoudene/Desktop/Devs/Venv/lib/python3.13/site-packages/rest_framework/serializers.py", line 251, in data
    self._data = self.to_representation(self.instance)
                 ~~~~~~~~~~~~~~~~~~~~~~^^^^^^^^^^^^^^^
  File "/Users/yassineelmoudene/Desktop/Devs/Venv/lib/python3.13/site-packages/rest_framework/serializers.py", line 716, in to_representation
    self.child.to_representation(item) for item in iterable
                                                   ^^^^^^^^
  File "/Users/yassineelmoudene/Desktop/Devs/Venv/lib/python3.13/site-packages/django/db/models/query.py", line 400, in __iter__
    self._fetch_all()
    ~~~~~~~~~~~~~~~^^
  File "/Users/yassineelmoudene/Desktop/Devs/Venv/lib/python3.13/site-packages/django/db/models/query.py", line 1928, in _fetch_all
    self._result_cache = list(self._iterable_class(self))
                         ~~~~^^^^^^^^^^^^^^^^^^^^^^^^^^^^
  File "/Users/yassineelmoudene/Desktop/Devs/Venv/lib/python3.13/site-packages/django/db/models/query.py", line 91, in __iter__
    results = compiler.execute_sql(
        chunked_fetch=self.chunked_fetch, chunk_size=self.chunk_size
    )
  File "/Users/yassineelmoudene/Desktop/Devs/Venv/lib/python3.13/site-packages/django/db/models/sql/compiler.py", line 1574, in execute_sql
    cursor.execute(sql, params)
    ~~~~~~~~~~~~~~^^^^^^^^^^^^^
  File "/Users/yassineelmoudene/Desktop/Devs/Venv/lib/python3.13/site-packages/django/db/backends/utils.py", line 122, in execute
    return super().execute(sql, params)
           ~~~~~~~~~~~~~~~^^^^^^^^^^^^^
  File "/Users/yassineelmoudene/Desktop/Devs/Venv/lib/python3.13/site-packages/django/db/backends/utils.py", line 79, in execute
    return self._execute_with_wrappers(
           ~~~~~~~~~~~~~~~~~~~~~~~~~~~^
        sql, params, many=False, executor=self._execute
        ^^^^^^^^^^^^^^^^^^^^^^^^^^^^^^^^^^^^^^^^^^^^^^^
    )
    ^
  File "/Users/yassineelmoudene/Desktop/Devs/Venv/lib/python3.13/site-packages/django/db/backends/utils.py", line 92, in _execute_with_wrappers
    return executor(sql, params, many, context)
  File "/Users/yassineelmoudene/Desktop/Devs/Venv/lib/python3.13/site-packages/django/db/backends/utils.py", line 100, in _execute
    with self.db.wrap_database_errors:
         ^^^^^^^^^^^^^^^^^^^^^^^^^^^^
  File "/Users/yassineelmoudene/Desktop/Devs/Venv/lib/python3.13/site-packages/django/db/utils.py", line 91, in __exit__
    raise dj_exc_value.with_traceback(traceback) from exc_value
  File "/Users/yassineelmoudene/Desktop/Devs/Venv/lib/python3.13/site-packages/django/db/backends/utils.py", line 105, in _execute
    return self.cursor.execute(sql, params)
           ~~~~~~~~~~~~~~~~~~~^^^^^^^^^^^^^
  File "/Users/yassineelmoudene/Desktop/Devs/Venv/lib/python3.13/site-packages/django/db/backends/mysql/base.py", line 76, in execute
    return self.cursor.execute(query, args)
           ~~~~~~~~~~~~~~~~~~~^^^^^^^^^^^^^
  File "/Users/yassineelmoudene/Desktop/Devs/Venv/lib/python3.13/site-packages/MySQLdb/cursors.py", line 179, in execute
    res = self._query(mogrified_query)
  File "/Users/yassineelmoudene/Desktop/Devs/Venv/lib/python3.13/site-packages/MySQLdb/cursors.py", line 330, in _query
    db.query(q)
    ~~~~~~~~^^^
  File "/Users/yassineelmoudene/Desktop/Devs/Venv/lib/python3.13/site-packages/MySQLdb/connections.py", line 261, in query
    _mysql.connection.query(self, query)
    ~~~~~~~~~~~~~~~~~~~~~~~^^^^^^^^^^^^^
django.db.utils.OperationalError: (1054, "Unknown column 'type_client.libelleTypeClient_fr' in 'field list'")
"GET /api/typeclients/ HTTP/1.1" 500 186075
"GET /api/statutaffaires/ HTTP/1.1" 200 2
"GET /api/tribunals/ HTTP/1.1" 200 2
"GET /api/typetribunals/ HTTP/1.1" 200 2
Internal Server Error: /api/typeclients/
Traceback (most recent call last):
  File "/Users/yassineelmoudene/Desktop/Devs/Venv/lib/python3.13/site-packages/django/db/backends/utils.py", line 105, in _execute
    return self.cursor.execute(sql, params)
           ~~~~~~~~~~~~~~~~~~~^^^^^^^^^^^^^
  File "/Users/yassineelmoudene/Desktop/Devs/Venv/lib/python3.13/site-packages/django/db/backends/mysql/base.py", line 76, in execute
    return self.cursor.execute(query, args)
           ~~~~~~~~~~~~~~~~~~~^^^^^^^^^^^^^
  File "/Users/yassineelmoudene/Desktop/Devs/Venv/lib/python3.13/site-packages/MySQLdb/cursors.py", line 179, in execute
    res = self._query(mogrified_query)
  File "/Users/yassineelmoudene/Desktop/Devs/Venv/lib/python3.13/site-packages/MySQLdb/cursors.py", line 330, in _query
    db.query(q)
    ~~~~~~~~^^^
  File "/Users/yassineelmoudene/Desktop/Devs/Venv/lib/python3.13/site-packages/MySQLdb/connections.py", line 261, in query
    _mysql.connection.query(self, query)
    ~~~~~~~~~~~~~~~~~~~~~~~^^^^^^^^^^^^^
MySQLdb.OperationalError: (1054, "Unknown column 'type_client.libelleTypeClient_fr' in 'field list'")

The above exception was the direct cause of the following exception:

Traceback (most recent call last):
  File "/Users/yassineelmoudene/Desktop/Devs/Venv/lib/python3.13/site-packages/django/core/handlers/exception.py", line 55, in inner
    response = get_response(request)
  File "/Users/yassineelmoudene/Desktop/Devs/Venv/lib/python3.13/site-packages/django/core/handlers/base.py", line 197, in _get_response
    response = wrapped_callback(request, *callback_args, **callback_kwargs)
  File "/Users/yassineelmoudene/Desktop/Devs/Venv/lib/python3.13/site-packages/django/views/decorators/csrf.py", line 65, in _view_wrapper
    return view_func(request, *args, **kwargs)
  File "/Users/yassineelmoudene/Desktop/Devs/Venv/lib/python3.13/site-packages/rest_framework/viewsets.py", line 125, in view
    return self.dispatch(request, *args, **kwargs)
           ~~~~~~~~~~~~~^^^^^^^^^^^^^^^^^^^^^^^^^^
  File "/Users/yassineelmoudene/Desktop/Devs/Venv/lib/python3.13/site-packages/rest_framework/views.py", line 515, in dispatch
    response = self.handle_exception(exc)
  File "/Users/yassineelmoudene/Desktop/Devs/Venv/lib/python3.13/site-packages/rest_framework/views.py", line 475, in handle_exception
    self.raise_uncaught_exception(exc)
    ~~~~~~~~~~~~~~~~~~~~~~~~~~~~~^^^^^
  File "/Users/yassineelmoudene/Desktop/Devs/Venv/lib/python3.13/site-packages/rest_framework/views.py", line 486, in raise_uncaught_exception
    raise exc
  File "/Users/yassineelmoudene/Desktop/Devs/Venv/lib/python3.13/site-packages/rest_framework/views.py", line 512, in dispatch
    response = handler(request, *args, **kwargs)
  File "/Users/yassineelmoudene/Desktop/Devs/Venv/lib/python3.13/site-packages/rest_framework/mixins.py", line 46, in list
    return Response(serializer.data)
                    ^^^^^^^^^^^^^^^
  File "/Users/yassineelmoudene/Desktop/Devs/Venv/lib/python3.13/site-packages/rest_framework/serializers.py", line 797, in data
    ret = super().data
          ^^^^^^^^^^^^
  File "/Users/yassineelmoudene/Desktop/Devs/Venv/lib/python3.13/site-packages/rest_framework/serializers.py", line 251, in data
    self._data = self.to_representation(self.instance)
                 ~~~~~~~~~~~~~~~~~~~~~~^^^^^^^^^^^^^^^
  File "/Users/yassineelmoudene/Desktop/Devs/Venv/lib/python3.13/site-packages/rest_framework/serializers.py", line 716, in to_representation
    self.child.to_representation(item) for item in iterable
                                                   ^^^^^^^^
  File "/Users/yassineelmoudene/Desktop/Devs/Venv/lib/python3.13/site-packages/django/db/models/query.py", line 400, in __iter__
    self._fetch_all()
    ~~~~~~~~~~~~~~~^^
  File "/Users/yassineelmoudene/Desktop/Devs/Venv/lib/python3.13/site-packages/django/db/models/query.py", line 1928, in _fetch_all
    self._result_cache = list(self._iterable_class(self))
                         ~~~~^^^^^^^^^^^^^^^^^^^^^^^^^^^^
  File "/Users/yassineelmoudene/Desktop/Devs/Venv/lib/python3.13/site-packages/django/db/models/query.py", line 91, in __iter__
    results = compiler.execute_sql(
        chunked_fetch=self.chunked_fetch, chunk_size=self.chunk_size
    )
  File "/Users/yassineelmoudene/Desktop/Devs/Venv/lib/python3.13/site-packages/django/db/models/sql/compiler.py", line 1574, in execute_sql
    cursor.execute(sql, params)
    ~~~~~~~~~~~~~~^^^^^^^^^^^^^
  File "/Users/yassineelmoudene/Desktop/Devs/Venv/lib/python3.13/site-packages/django/db/backends/utils.py", line 122, in execute
    return super().execute(sql, params)
           ~~~~~~~~~~~~~~~^^^^^^^^^^^^^
  File "/Users/yassineelmoudene/Desktop/Devs/Venv/lib/python3.13/site-packages/django/db/backends/utils.py", line 79, in execute
    return self._execute_with_wrappers(
           ~~~~~~~~~~~~~~~~~~~~~~~~~~~^
        sql, params, many=False, executor=self._execute
        ^^^^^^^^^^^^^^^^^^^^^^^^^^^^^^^^^^^^^^^^^^^^^^^
    )
    ^
  File "/Users/yassineelmoudene/Desktop/Devs/Venv/lib/python3.13/site-packages/django/db/backends/utils.py", line 92, in _execute_with_wrappers
    return executor(sql, params, many, context)
  File "/Users/yassineelmoudene/Desktop/Devs/Venv/lib/python3.13/site-packages/django/db/backends/utils.py", line 100, in _execute
    with self.db.wrap_database_errors:
         ^^^^^^^^^^^^^^^^^^^^^^^^^^^^
  File "/Users/yassineelmoudene/Desktop/Devs/Venv/lib/python3.13/site-packages/django/db/utils.py", line 91, in __exit__
    raise dj_exc_value.with_traceback(traceback) from exc_value
  File "/Users/yassineelmoudene/Desktop/Devs/Venv/lib/python3.13/site-packages/django/db/backends/utils.py", line 105, in _execute
    return self.cursor.execute(sql, params)
           ~~~~~~~~~~~~~~~~~~~^^^^^^^^^^^^^
  File "/Users/yassineelmoudene/Desktop/Devs/Venv/lib/python3.13/site-packages/django/db/backends/mysql/base.py", line 76, in execute
    return self.cursor.execute(query, args)
           ~~~~~~~~~~~~~~~~~~~^^^^^^^^^^^^^
  File "/Users/yassineelmoudene/Desktop/Devs/Venv/lib/python3.13/site-packages/MySQLdb/cursors.py", line 179, in execute
    res = self._query(mogrified_query)
  File "/Users/yassineelmoudene/Desktop/Devs/Venv/lib/python3.13/site-packages/MySQLdb/cursors.py", line 330, in _query
    db.query(q)
    ~~~~~~~~^^^
  File "/Users/yassineelmoudene/Desktop/Devs/Venv/lib/python3.13/site-packages/MySQLdb/connections.py", line 261, in query
    _mysql.connection.query(self, query)
    ~~~~~~~~~~~~~~~~~~~~~~~^^^^^^^^^^^^^
django.db.utils.OperationalError: (1054, "Unknown column 'type_client.libelleTypeClient_fr' in 'field list'")
"GET /api/typeclients/ HTTP/1.1" 500 186075
/Users/yassineelmoudene/Desktop/Devs/avocat_web/api/migrations/0001_initial.py changed, reloading.
Watching for file changes with StatReloader
/Users/yassineelmoudene/Desktop/Devs/avocat_web/api/migrations/0001_initial.py changed, reloading.
Watching for file changes with StatReloader
/Users/yassineelmoudene/Desktop/Devs/avocat_web/api/models.py changed, reloading.
Watching for file changes with StatReloader
"GET /api/statutaffaires/ HTTP/1.1" 401 172
"GET /api/affairejudiciaires/ HTTP/1.1" 401 172
"GET /api/clients/ HTTP/1.1" 401 172
"GET /api/typeclients/ HTTP/1.1" 401 172
"GET /api/fonctionclients/ HTTP/1.1" 401 172
"GET /api/typeaffaires/ HTTP/1.1" 401 172
"POST /api/token/ HTTP/1.1" 200 628
"GET /api/clients/ HTTP/1.1" 200 2
"GET /api/typeaffaires/ HTTP/1.1" 200 2
"GET /api/affairejudiciaires/ HTTP/1.1" 200 2
"GET /api/fonctionclients/ HTTP/1.1" 200 2
"GET /api/statutaffaires/ HTTP/1.1" 200 2
"GET /api/typeclients/ HTTP/1.1" 200 2
"GET /api/clients/ HTTP/1.1" 200 2
"GET /api/typeclients/ HTTP/1.1" 200 2
"GET /api/fonctionclients/ HTTP/1.1" 200 2
"GET /api/statutaffaires/ HTTP/1.1" 200 2
"GET /api/tribunals/ HTTP/1.1" 200 2
"GET /api/typetribunals/ HTTP/1.1" 200 2
"GET /api/typeclients/ HTTP/1.1" 200 2
"GET /api/clients/ HTTP/1.1" 200 2
"GET /api/clients/ HTTP/1.1" 200 2
"GET /api/typeclients/ HTTP/1.1" 200 2
"GET /api/typeaffaires/ HTTP/1.1" 200 2
"GET /api/statutaffaires/ HTTP/1.1" 200 2
"GET /api/affairejudiciaires/ HTTP/1.1" 200 2
"GET /api/fonctionclients/ HTTP/1.1" 200 2
"GET /api/audiences/?future_only=true HTTP/1.1" 200 2
"GET /api/fonctionclients/ HTTP/1.1" 200 2
"GET /api/statutaffaires/ HTTP/1.1" 200 2
"GET /api/typeclients/ HTTP/1.1" 200 2
"GET /api/statutaffaires/ HTTP/1.1" 200 2
"GET /api/tribunals/ HTTP/1.1" 200 2
"GET /api/typetribunals/ HTTP/1.1" 200 2
"GET /api/typetribunals/ HTTP/1.1" 200 2
"POST /api/typetribunals/ HTTP/1.1" 400 82
"GET /api/typeclients/ HTTP/1.1" 200 2
"POST /api/typeclients/ HTTP/1.1" 201 129
"GET /api/typeclients/ HTTP/1.1" 200 131
"POST /api/typeclients/ HTTP/1.1" 201 111
"GET /api/typeclients/ HTTP/1.1" 200 243
"GET /api/statutaffaires/ HTTP/1.1" 200 2
"POST /api/statutaffaires/ HTTP/1.1" 400 85
